Workbook

Sheet BD_Clez_Premigracion
A1: # de documento | B1: Afiliado | C1: Cedula | D1: DirecciÃ³n | E1: Telefono | F1: Email | G1: Valor | H1: Sucursal | I1: Plan / Producto | J1: Canal | K1: Fuente | L1: Medio | M1: CampaÃ±a | N1: Estado | O1: Forma de Pago | P1: Fecha | Q1: Cedula usuario que registro | R1: Usuario que registro | S1: Entrenador | T1: Usuario que suplanta | U1: Tipo | V1: Motivo | W1: Observaciones Documento | X1: Â¿Tuvo cortesia? | Y1: GestiÃ³n CRM | Z1: Tipo Afiliado | AA1: FacturaciÃ³n electronica | AB1: Firmada | AC1: Se encentra en FP+
A2: FPF-33558 | B2: LAURIN VANESSA MONTAÂ¥O SANTIAGO | C2: 1091652989 | D2: cra 19 17 - 65 | E2: 3115583628 | F2: laurinsvanesa31@gmail.com | G2: 89 | H2: Boulevard | I2: PLAN DEBITO AUTOMÃ¡TICO POR 89.000 (PERMANENCIA 12 MESES) | J2: On Line | N2: Activo | O2: PAGOS ON LINE / CLEZ PAY-89000.00 | P2: 45946.764 | Q2: 7777777 | R2: CLEZ | U2: Factura de Venta | W2: Facturado automaticamente por CLEZ PAY Facturado automaticamente por CLEZ PAY | X2: No | Y2: Si | Z2: Renovado | AA2: No enviada | AB2: No | AC2: =IFERROR(VLOOKUP(C2,MigradosEfectivamente!B:B,1,FALSE),"No encontrado") -> No encontrado
A3: FP-34356 | B3: JUAN FERNANDO ARAUJO LAZCANO | C3: 1050918470 | D3: PROVENZA | E3: 3243181439 | F3: jaraujolazcano@gmail.com | G3: 89 | H3: Provenza | I3: PLAN DEBITO AUTOMÃ¡TICO POR 89.000 (PERMANENCIA 12 MESES) | J3: On Line | N3: Activo | O3: PAGOS ON LINE / CLEZ PAY-89000.00 | P3: 45946.713 | Q3: 7777777 | R3: CLEZ | U3: Factura de Venta | W3: Facturado automaticamente por CLEZ PAY Facturado automaticamente por CLEZ PAY | X3: No | Y3: Si | Z3: Renovado | AA3: Enviada | AB3: No | AC3: =IFERROR(VLOOKUP(C3,MigradosEfectivamente!B:B,1,FALSE),"No encontrado") -> No encontrado
A4: FC-65942 | B4: VALENTINA SAVEDRA HOYOS | C4: 1030542921 | D4: Calle 64#2w76 Mutis | E4: 3196218540 | F4: valentinahoyos77@gmail.com | G4: 89 | H4: Ciudadela | I4: PLAN DEBITO AUTOMÃ¡TICO POR 89.000 (PERMANENCIA 12 MESES) | J4: On Line | N4: Activo | O4: PAGOS ON LINE / CLEZ PAY-89000.00 | P4: 45946.683 | Q4: 7777777 | R4: CLEZ | U4: Factura de Venta | W4: Facturado automaticamente por CLEZ PAY Facturado automaticamente por CLEZ PAY | X4: Si | Y4: Si | Z4: Renovado | AA4: Enviada | AB4: No | AC4: =IFERROR(VLOOKUP(C4,MigradosEfectivamente!B:B,1,FALSE),"No encontrado") -> 1030542921
A5: FPP-26926 | B5: ASURY ALEJANDRA RENOGA RENOGA | C5: 1004823152 | D5: PIEDECUESTA | E5: 3224708688 | F5: pa318344@gmail.com | G5: 89 | H5: Piedecuesta | I5: PLAN DEBITO AUTOMÃ¡TICO POR 89.000 (PERMANENCIA 12 MESES) | J5: On Line | N5: Activo | O5: PAGOS ON LINE / CLEZ PAY-89000.00 | P5: 45945.586 | Q5: 7777777 | R5: CLEZ | U5: Factura de Venta | W5: Facturado automaticamente por CLEZ PAY (Cron cobro suscripcion) Facturado automaticamente por CLEZ PAY (Cron cobro suscripcion) | X5: No | Y5: Si | Z5: Renovado | AA5: No enviada | AB5: No | AC5: =IFERROR(VLOOKUP(C5,MigradosEfectivamente!B:B,1,FALSE),"No encontrado") -> No encontrado
A6: FP-34329 | B6: LILIAM MAYERLIS CABRERA ARAUJO | C6: 1002295958 | D6: PROVENZA | E6: 57 301 4934088 | F6: Cabreraaraujo2003@gmail.com | G6: 89 | H6: Provenza | I6: PLAN DEBITO AUTOMÃ¡TICO POR 89.000 (PERMANENCIA 12 MESES) | J6: On Line | N6: Activo | O6: PAGOS ON LINE / CLEZ PAY-89000.00 | P6: 45944.486 | Q6: 7777777 | R6: CLEZ | U6: Factura de Venta | W6: Facturado automaticamente por CLEZ PAY Facturado automaticamente por CLEZ PAY | X6: No | Y6: Si | Z6: Renovado | AA6: No enviada | AB6: No | AC6: =IFERROR(VLOOKUP(C6,MigradosEfectivamente!B:B,1,FALSE),"No encontrado") -> No encontrado
A7: CE-12471 | B7: ALEJANDRA RAMÃREZ | C7: 1092349320 | D7: Calle 11 an 11 ae 68 conjunto torres del centenario, torre Santander apto 802 | E7: 3132352718 | F7: ramirezalejandra56@gmail.com | G7: 89 | H7: Ceiba | I7: PLAN DEBITO AUTOMÃ¡TICO POR 89.000 (PERMANENCIA 12 MESES) | J7: On Line | N7: Activo | O7: PAGOS ON LINE / CLEZ PAY-89000.00 | P7: 45940.585 | Q7: 7777777 | R7: CLEZ | U7: Factura de Venta | W7: Facturado automaticamente por CLEZ PAY (Cron cobro suscripcion) Facturado automaticamente por CLEZ PAY (Cron cobro suscripcion) | X7: No | Y7: Si | Z7: Nuevo | AA7: Enviada | AB7: No | AC7: =IFERROR(VLOOKUP(C7,MigradosEfectivamente!B:B,1,FALSE),"No encontrado") -> No encontrado
A8: FP-34313 | B8: ZORELISA FIGUEROA SAAVEDRA | C8: 1050918718 | D8: PROVENZA | E8: 3128293091 | F8: zorelisafigueroa1705@gmail.com | G8: 89 | H8: Provenza | I8: PLAN DEBITO AUTOMÃ¡TICO POR 89.000 (PERMANENCIA 12 MESES) | J8: On Line | N8: Activo | O8: PAGOS ON LINE / CLEZ PAY-89000.00 | P8: 45940.49 | Q8: 7777777 | R8: CLEZ | U8: Factura de Venta | W8: Facturado automaticamente por CLEZ PAY Facturado automaticamente por CLEZ PAY | X8: No | Y8: Si | Z8: Renovado | AA8: Enviada | AB8: No | AC8: =IFERROR(VLOOKUP(C8,MigradosEfectivamente!B:B,1,FALSE),"No encontrado") -> No encontrado
A9: FP-34310 | B9: DANIEL RODRIGUEZ | C9: 1142716057 | D9: Av 87 #20-134 | E9: 3205124628 | F9: sandoval.rodriguez.danielsn@gmail.com | G9: 89 | H9: Provenza | I9: PLAN DEBITO AUTOMÃ¡TICO POR 89.000 (PERMANENCIA 12 MESES) | J9: On Line | N9: Activo | O9: PAGOS ON LINE / CLEZ PAY-89000.00 | P9: 45940.338 | Q9: 7777777 | R9: CLEZ | U9: Factura de Venta | W9: Facturado automaticamente por CLEZ PAY (Cron cobro suscripcion) Facturado automaticamente por CLEZ PAY (Cron cobro suscripcion) | X9: No | Y9: Si | Z9: Renovado | AA9: Enviada | AB9: No | AC9: =IFERROR(VLOOKUP(C9,MigradosEfectivamente!B:B,1,FALSE),"No encontrado") -> No encontrado
A10: CE-12464 | B10: YEISON ALEXANDER PEDRAZA ARDILA | C10: 1005025225 | D10: cucuta | E10: 3022747153 | F10: PEDRAZA1134@GMAIL.COM | G10: 99 | H10: Ceiba | I10: PLAN DEBITO AUTOMÃ¡TICO POR 99.000 (PERMANENCIA 12 MESES) | J10: On Line | N10: Activo | O10: PAGOS ON LINE / CLEZ PAY-99000.00 | P10: 45940.337 | Q10: 7777777 | R10: CLEZ | U10: Factura de Venta | W10: Facturado automaticamente por CLEZ PAY (Cron cobro suscripcion) Facturado automaticamente por CLEZ PAY (Cron cobro suscripcion) | X10: Si | Y10: Si | Z10: Renovado | AA10: Enviada | AB10: No | AC10: =IFERROR(VLOOKUP(C10,MigradosEfectivamente!B:B,1,FALSE),"No encontrado") -> No encontrado
A11: CE-12463 | B11: OMAR CASTELLANO | C11: 5004717783 | D11: Calle 1N #0a-24 edificio rosmar | E11: 3017550017 | F11: chitomeio@hotmail.com | G11: 99 | H11: Ceiba | I11: PLAN DEBITO AUTOMÃ¡TICO POR 99.000 (PERMANENCIA 12 MESES) | J11: On Line | N11: Activo | O11: PAGOS ON LINE / CLEZ PAY-99000.00 | P11: 45940.334 | Q11: 7777777 | R11: CLEZ | U11: Factura de Venta | W11: Facturado automaticamente por CLEZ PAY (Cron cobro suscripcion) Facturado automaticamente por CLEZ PAY (Cron cobro suscripcion) | X11: No | Y11: Si | Z11: Renovado | AA11: Enviada | AB11: No | AC11: =IFERROR(VLOOKUP(C11,MigradosEfectivamente!B:B,1,FALSE),"No encontrado") -> No encontrado
A12: FC-65883 | B12: MARIA ALEJANDRA RODRIGUEZ REYES | C12: 1098801968 | D12: SAN FRANCISCO | E12: 3186962347 | F12: marialejandrarr25@gmail.com | G12: 89 | H12: Ciudadela | I12: PLAN DEBITO AUTOMÃ¡TICO POR 89.000 (PERMANENCIA 12 MESES) | J12: On Line | N12: Activo | O12: PAGOS ON LINE / CLEZ PAY-89000.00 | P12: 45939.876 | Q12: 7777777 | R12: CLEZ | U12: Factura de Venta | W12: Facturado automaticamente por CLEZ PAY (Cron cobro suscripcion) Facturado automaticamente por CLEZ PAY (Cron cobro suscripcion) | X12: No | Y12: Si | Z12: Recuperado | AA12: Enviada | AB12: No | AC12: =IFERROR(VLOOKUP(C12,MigradosEfectivamente!B:B,1,FALSE),"No encontrado") -> No encontrado
A13: PR-1731 | B13: CARLOS SANTIAGO GARCIA BARRERA | C13: 1097093302 | D13: Calle 22 #24-65 | E13: 3184407645 | F13: casagaba33@gmail.com | G13: 89 | H13: El Prado | I13: PLAN DEBITO AUTOMÃ¡TICO POR 89.000 (PERMANENCIA 12 MESES) | J13: On Line | N13: Activo | O13: PAGOS ON LINE / CLEZ PAY-89000.00 | P13: 45939.876 | Q13: 7777777 | R13: CLEZ | U13: Factura de Venta | W13: Facturado automaticamente por CLEZ PAY (Cron cobro suscripcion) Facturado automaticamente por CLEZ PAY (Cron cobro suscripcion) | X13: No | Y13: No | Z13: Renovado | AA13: Enviada | AB13: No | AC13: =IFERROR(VLOOKUP(C13,MigradosEfectivamente!B:B,1,FALSE),"No encontrado") -> No encontrado
A14: FPP-26906 | B14: GUSTAVO DIAZ | C14: 1098724742 | D14: AVEN 10N 17-92 | E14: 3155151739 | F14: gdiaz420@unab.edu.co | G14: 89 | H14: Piedecuesta | I14: PLAN DEBITO AUTOMÃ¡TICO POR 89.000 (PERMANENCIA 12 MESES) | J14: On Line | N14: Activo | O14: PAGOS ON LINE / CLEZ PAY-89000.00 | P14: 45939.587 | Q14: 7777777 | R14: CLEZ | U14: Factura de Venta | W14: Facturado automaticamente por CLEZ PAY (Cron cobro suscripcion) Facturado automaticamente por CLEZ PAY (Cron cobro suscripcion) | X14: Si | Y14: Si | Z14: Renovado | AA14: Enviada | AB14: No | AC14: =IFERROR(VLOOKUP(C14,MigradosEfectivamente!B:B,1,FALSE),"No encontrado") -> No encontrado
A15: PR-1729 | B15: JORGE LUIS MARTINEZ MARQUEZ | C15: 1007469498 | D15: CABECERA | E15: 3013919131 | F15: jorge.luis082000@gmail.com | G15: 89 | H15: El Prado | I15: PLAN DEBITO AUTOMÃ¡TICO POR 89.000 (PERMANENCIA 12 MESES) | J15: On Line | N15: Activo | O15: PAGOS ON LINE / CLEZ PAY-89000.00 | P15: 45939.586 | Q15: 7777777 | R15: CLEZ | U15: Factura de Venta | W15: Facturado automaticamente por CLEZ PAY (Cron cobro suscripcion) Facturado automaticamente por CLEZ PAY (Cron cobro suscripcion) | X15: No | Y15: Si | Z15: Renovado | AA15: Enviada | AB15: No | AC15: =IFERROR(VLOOKUP(C15,MigradosEfectivamente!B:B,1,FALSE),"No encontrado") -> No encontrado
A16: CB-8988 | B16: BRAYAN DAVID VALBUENA GELVEZ | C16: 1005326464 | D16: cabecera | E16: 3158275763 | F16: brayanvg2002@gmail.com | G16: 99 | H16: Cabecera | I16: PLAN DEBITO AUTOMÃ¡TICO POR 99.000 (PERMANENCIA 12 MESES) | J16: On Line | N16: Activo | O16: PAGOS ON LINE / CLEZ PAY-99000.00 | P16: 45939.337 | Q16: 7777777 | R16: CLEZ | U16: Factura de Venta | W16: Facturado automaticamente por CLEZ PAY (Cron cobro suscripcion) Facturado automaticamente por CLEZ PAY (Cron cobro suscripcion) | X16: No | Y16: Si | Z16: Renovado | AA16: Enviada | AB16: No | AC16: =IFERROR(VLOOKUP(C16,MigradosEfectivamente!B:B,1,FALSE),"No encontrado") -> No encontrado
A17: CB-8987 | B17: JULIAN CAMILO GOMEZ JAIME | C17: 1098650766 | D17: CABECERA | E17: 319 4146653 | F17: juliangomezjaime@gmail.com | G17: 89 | H17: Cabecera | I17: PLAN DEBITO AUTOMÃ¡TICO POR 89.000 (PERMANENCIA 12 MESES) | J17: On Line | N17: Activo | O17: PAGOS ON LINE / CLEZ PAY-89000.00 | P17: 45939.337 | Q17: 7777777 | R17: CLEZ | U17: Factura de Venta | W17: Facturado automaticamente por CLEZ PAY (Cron cobro suscripcion) Facturado automaticamente por CLEZ PAY (Cron cobro suscripcion) | X17: No | Y17: Si | Z17: Renovado | AA17: Enviada | AB17: No | AC17: =IFERROR(VLOOKUP(C17,MigradosEfectivamente!B:B,1,FALSE),"No encontrado") -> No encontrado
A18: CE-12451 | B18: JORGE LUIS GARCÃ‰S | C18: 72159538 | D18: Calle 4a #16-13 barrio san CristÃ³bal . Piedecuesta | E18: 3165357372 | F18: propio.35@hotmail.com | G18: 89 | H18: Ceiba | I18: PLAN DEBITO AUTOMATICO LOS PRIMER 3 MESES $49.900 DESDE EL CUARTO MES 89.000 (PERMANENCIA 12 MESES) | J18: On Line | N18: Activo | O18: PAGOS ON LINE / CLEZ PAY-89000.00 | P18: 45939.337 | Q18: 7777777 | R18: CLEZ | U18: Factura de Venta | W18: Facturado automaticamente por CLEZ PAY (Cron cobro suscripcion) Facturado automaticamente por CLEZ PAY (Cron cobro suscripcion) | X18: No | Y18: No | Z18: Renovado | AA18: Enviada | AB18: No | AC18: =IFERROR(VLOOKUP(C18,MigradosEfectivamente!B:B,1,FALSE),"No encontrado") -> No encontrado
A19: CB-8986 | B19: ANDREA CAROLINA REYES RODRIGUEZ | C19: 5692729 | D19: bucaramanga | E19: 3185468442 | F19: acreyesrodriguez@gmail.com | G19: 99 | H19: Cabecera | I19: PLAN DEBITO AUTOMÃ¡TICO POR 99.000 (PERMANENCIA 12 MESES) | J19: On Line | N19: Activo | O19: PAGOS ON LINE / CLEZ PAY-99000.00 | P19: 45939.334 | Q19: 7777777 | R19: CLEZ | U19: Factura de Venta | W19: Facturado automaticamente por CLEZ PAY (Cron cobro suscripcion) Facturado automaticamente por CLEZ PAY (Cron cobro suscripcion) | X19: No | Y19: Si | Z19: Renovado | AA19: Enviada | AB19: No | AC19: =IFERROR(VLOOKUP(C19,MigradosEfectivamente!B:B,1,FALSE),"No encontrado") -> No encontrado
A20: PR-1727 | B20: JOSEPH RODRIGUEZ | C20: 1098764267 | D20: Calle 36 33 44 | E20: 3177195428 | F20: josephr1326@gmail.com | G20: 89 | H20: El Prado | I20: PLAN DEBITO AUTOMÃ¡TICO POR 99.000 (PERMANENCIA 12 MESES) | J20: On Line | N20: Activo | O20: PAGOS ON LINE / CLEZ PAY-89000.00 | P20: 45939.334 | Q20: 7777777 | R20: CLEZ | U20: Factura de Venta | W20: Facturado automaticamente por CLEZ PAY (Cron cobro suscripcion) Facturado automaticamente por CLEZ PAY (Cron cobro suscripcion) | X20: No | Y20: No | Z20: Renovado | AA20: Enviada | AB20: No | AC20: =IFERROR(VLOOKUP(C20,MigradosEfectivamente!B:B,1,FALSE),"No encontrado") -> No encontrado
A21: CE-12439 | B21: JHON ANDEERSON MONTAÃ‘EZ HERNANDEZ | C21: 1091352306 | D21: calle 22an #2-110 Prados norte | E21: 3104194505 | F21: montanezjhon824@gmail.com | G21: 89 | H21: Ceiba | I21: PLAN DEBITO AUTOMÃ¡TICO POR 99.000 (PERMANENCIA 12 MESES) | J21: On Line | N21: Activo | O21: PAGOS ON LINE / CLEZ PAY-89000.00 | P21: 45938.588 | Q21: 7777777 | R21: CLEZ | U21: Factura de Venta | W21: Facturado automaticamente por CLEZ PAY (Cron cobro suscripcion) Facturado automaticamente por CLEZ PAY (Cron cobro suscripcion) | X21: Si | Y21: Si | Z21: Renovado | AA21: Enviada | AB21: No | AC21: =IFERROR(VLOOKUP(C21,MigradosEfectivamente!B:B,1,FALSE),"No encontrado") -> No encontrado
A22: FPNS-30952 | B22: TANIA ALEJANDRA BERNAL GUEVARA | C22: 1093751069 | D22: conjunto bonaire | E22: 3182330939 | F22: bernaltaniaguevara@gmail.com | G22: 349 | H22: Cucuta | I22: CLEZ 4 MESES DELUXE | J22: On Line | N22: Activo | O22: PAGOS ON LINE / CLEZ PAY-349000.00 | P22: 45938.442 | Q22: 7777777 | R22: CLEZ | U22: Factura de Venta | W22: Facturado automaticamente por CLEZ PAY Facturado automaticamente por CLEZ PAY | X22: No | Y22: Si | Z22: Recuperado | AA22: Enviada | AB22: No | AC22: =IFERROR(VLOOKUP(C22,MigradosEfectivamente!B:B,1,FALSE),"No encontrado") -> No encontrado
A23: CE-12432 | B23: MANUELA VALENTINA SERNA QUIÃ‘ONEZ | C23: 1091356063 | D23: bucaramanga | E23: 3017290615 | F23: notien@gmail.com | G23: 89 | H23: Ceiba | I23: PLAN DEBITO AUTOMÃ¡TICO POR 99.000 (PERMANENCIA 12 MESES) | J23: On Line | N23: Activo | O23: PAGOS ON LINE / CLEZ PAY-89000.00 | P23: 45938.338 | Q23: 7777777 | R23: CLEZ | U23: Factura de Venta | W23: Facturado automaticamente por CLEZ PAY (Cron cobro suscripcion) Facturado automaticamente por CLEZ PAY (Cron cobro suscripcion) | X23: No | Y23: Si | Z23: Renovado | AA23: Enviada | AB23: No | AC23: =IFERROR(VLOOKUP(C23,MigradosEfectivamente!B:B,1,FALSE),"No encontrado") -> No encontrado
A24: FPF-33461 | B24: STEPHANIE FERNANDA ARENAS RIVERA | C24: 1096702367 | D24: SAN FRANCISCO | E24: 3125072124 | F24: dprivera21@gmail.com | G24: 89 | H24: Boulevard | I24: PLAN DEBITO AUTOMÃ¡TICO POR 89.000 (PERMANENCIA 12 MESES) | J24: On Line | N24: Activo | O24: PAGOS ON LINE / CLEZ PAY-89000.00 | P24: 45938.337 | Q24: 7777777 | R24: CLEZ | U24: Factura de Venta | W24: Facturado automaticamente por CLEZ PAY (Cron cobro suscripcion) Facturado automaticamente por CLEZ PAY (Cron cobro suscripcion) | X24: No | Y24: Si | Z24: Renovado | AA24: Enviada | AB24: No | AC24: =IFERROR(VLOOKUP(C24,MigradosEfectivamente!B:B,1,FALSE),"No encontrado") -> No encontrado
A25: FPF-33460 | B25: LUIS DAVID GALVAN HERNANDEZ | C25: 1096803416 | D25: SAN FRANCISCO | E25: 3102142101 | F25: luisymarta1@gmail.com | G25: 89 | H25: Boulevard | I25: PLAN DEBITO AUTOMÃ¡TICO POR 89.000 (PERMANENCIA 12 MESES) | J25: On Line | N25: Activo | O25: PAGOS ON LINE / CLEZ PAY-89000.00 | P25: 45938.335 | Q25: 7777777 | R25: CLEZ | U25: Factura de Venta | W25: Facturado automaticamente por CLEZ PAY (Cron cobro suscripcion) Facturado automaticamente por CLEZ PAY (Cron cobro suscripcion) | X25: No | Y25: Si | Z25: Renovado | AA25: Enviada | AB25: No | AC25: =IFERROR(VLOOKUP(C25,MigradosEfectivamente!B:B,1,FALSE),"No encontrado") -> No encontrado
A26: FPNS-30950 | B26: JOSE MARIO DIAZ | C26: 1003232144 | D26: Cucuta | E26: 3007622574 | F26: Pendiente@gmail.com | G26: 99 | H26: Cucuta | I26: PLAN DEBITO AUTOMÃ¡TICO POR 99.000 (PERMANENCIA 12 MESES) | J26: On Line | N26: Activo | O26: PAGOS ON LINE / CLEZ PAY-99000.00 | P26: 45937.878 | Q26: 7777777 | R26: CLEZ | U26: Factura de Venta | W26: Facturado automaticamente por CLEZ PAY (Cron cobro suscripcion) Facturado automaticamente por CLEZ PAY (Cron cobro suscripcion) | X26: Si | Y26: Si | Z26: Renovado | AA26: No enviada | AB26: No | AC26: =IFERROR(VLOOKUP(C26,MigradosEfectivamente!B:B,1,FALSE),"No encontrado") -> No encontrado
A27: FP-34291 | B27: ALBERTO SERRANO RINCON | C27: 91269649 | D27: CRA 22 #110-31 | E27: 3013085558 | F27: YAENISERRANO@GMAIL.COM | G27: 89 | H27: Provenza | I27: PLAN DEBITO AUTOMÃ¡TICO POR 89.000 (PERMANENCIA 12 MESES) | J27: On Line | N27: Activo | O27: PAGOS ON LINE / CLEZ PAY-89000.00 | P27: 45937.773 | Q27: 7777777 | R27: CLEZ | U27: Factura de Venta | W27: Facturado automaticamente por CLEZ PAY Facturado automaticamente por CLEZ PAY | X27: No | Y27: Si | AA27: Enviada | AB27: No | AC27: =IFERROR(VLOOKUP(C27,MigradosEfectivamente!B:B,1,FALSE),"No encontrado") -> No encontrado
A28: FC-65853 | B28: ANGELA , HERNANDEZ ACEVEDO | C28: 1098791712 | D28: cll 57 7 61 | E28: 3172858734 | F28: angelahdez_29@hotmail.com | G28: 89 | H28: Ciudadela | I28: PLAN DEBITO AUTOMÃ¡TICO POR 99.000 (PERMANENCIA 12 MESES) | J28: On Line | N28: Activo | O28: PAGOS ON LINE / CLEZ PAY-89000.00 | P28: 45937.587 | Q28: 7777777 | R28: CLEZ | U28: Factura de Venta | W28: Facturado automaticamente por CLEZ PAY (Cron cobro suscripcion) Facturado automaticamente por CLEZ PAY (Cron cobro suscripcion) | X28: Si | Y28: Si | Z28: Renovado | AA28: Enviada | AB28: No | AC28: =IFERROR(VLOOKUP(C28,MigradosEfectivamente!B:B,1,FALSE),"No encontrado") -> No encontrado
A29: PR-1714 | B29: MARIA DUARTE | C29: 1101623131 | D29: Calle 33#30-35 apto 504 edificio pentagrama | E29: 3166473269 | F29: mariaalejandraduarte@gmail.com | G29: 89 | H29: El Prado | I29: PLAN DEBITO AUTOMÃ¡TICO POR 89.000 (PERMANENCIA 12 MESES) | J29: On Line | N29: Activo | O29: PAGOS ON LINE / CLEZ PAY-89000.00 | P29: 45937.586 | Q29: 7777777 | R29: CLEZ | U29: Factura de Venta | W29: Facturado automaticamente por CLEZ PAY (Cron cobro suscripcion) Facturado automaticamente por CLEZ PAY (Cron cobro suscripcion) | X29: No | Y29: Si | Z29: Nuevo | AA29: Enviada | AB29: No | AC29: =IFERROR(VLOOKUP(C29,MigradosEfectivamente!B:B,1,FALSE),"No encontrado") -> No encontrado
A30: FC-65852 | B30: KEVIN DANIEL INFANTE HERNANDEZ | C30: 1098826076 | D30: cll 59 7 61 | E30: 3012379223 | F30: kevinfante25@gmail.com | G30: 89 | H30: Ciudadela | I30: PLAN DEBITO AUTOMÃ¡TICO POR 99.000 (PERMANENCIA 12 MESES) | J30: On Line | N30: Activo | O30: PAGOS ON LINE / CLEZ PAY-89000.00 | P30: 45937.584 | Q30: 7777777 | R30: CLEZ | U30: Factura de Venta | W30: Facturado automaticamente por CLEZ PAY (Cron cobro suscripcion) Facturado automaticamente por CLEZ PAY (Cron cobro suscripcion) | X30: No | Y30: Si | Z30: Renovado | AA30: Enviada | AB30: No | AC30: =IFERROR(VLOOKUP(C30,MigradosEfectivamente!B:B,1,FALSE),"No encontrado") -> No encontrado
A31: FP-34286 | B31: SANDRA ELOINA PABON MORA | C31: 27652502 | D31: BUCARAMANGA | E31: 314 2417309 | F31: sandraeloinapm1983@gmail.com | G31: 89 | H31: Provenza | I31: PLAN DEBITO AUTOMÃ¡TICO POR 89.000 (PERMANENCIA 12 MESES) | J31: On Line | N31: Activo | O31: PAGOS ON LINE / CLEZ PAY-89000.00 | P31: 45937.444 | Q31: 7777777 | R31: CLEZ | U31: Factura de Venta | W31: Facturado automaticamente por CLEZ PAY Facturado automaticamente por CLEZ PAY | X31: No | Y31: Si | Z31: Renovado | AA31: Enviada | AB31: No | AC31: =IFERROR(VLOOKUP(C31,MigradosEfectivamente!B:B,1,FALSE),"No encontrado") -> No encontrado
A32: CB-8963 | B32: PAULA ANDREA PEÃ‘ATE NATERA | C32: 1048217134 | D32: cabecera | E32: 301 7073231 | F32: paula07andrea@hotmail.com | G32: 89 | H32: Cabecera | I32: PLAN DEBITO AUTOMÃ¡TICO POR 89.000 (PERMANENCIA 12 MESES) | J32: On Line | N32: Activo | O32: PAGOS ON LINE / CLEZ PAY-89000.00 | P32: 45937.336 | Q32: 7777777 | R32: CLEZ | U32: Factura de Venta | W32: Facturado automaticamente por CLEZ PAY (Cron cobro suscripcion) Facturado automaticamente por CLEZ PAY (Cron cobro suscripcion) | X32: No | Y32: Si | Z32: Renovado | AA32: Enviada | AB32: No | AC32: =IFERROR(VLOOKUP(C32,MigradosEfectivamente!B:B,1,FALSE),"No encontrado") -> No encontrado
A33: FPF-33444 | B33: ANGIE MONTOYA | C33: 1005261067 | D33: Carrera 41 D No.203-239 Los Andes-Floridablanca | E33: 3160447671 | F33: angiemontoyaluna02@gmail.com | G33: 89 | H33: Canaveral | I33: PLAN DEBITO AUTOMÃ¡TICO POR 89.000 (PERMANENCIA 12 MESES) | J33: On Line | N33: Activo | O33: PAGOS ON LINE / CLEZ PAY-89000.00 | P33: 45937.336 | Q33: 7777777 | R33: CLEZ | U33: Factura de Venta | W33: Facturado automaticamente por CLEZ PAY (Cron cobro suscripcion) Facturado automaticamente por CLEZ PAY (Cron cobro suscripcion) | X33: No | Y33: Si | Z33: Renovado | AA33: Enviada | AB33: No | AC33: =IFERROR(VLOOKUP(C33,MigradosEfectivamente!B:B,1,FALSE),"No encontrado") -> No encontrado
A34: CE-12406 | B34: JENNIFER SILVA | C34: 1004844070 | D34: calle 23n 4-114 prados norte | E34: 3154611341 | F34: jenifercasilva@outlook.es | G34: 99 | H34: Ceiba | I34: PLAN DEBITO AUTOMÃ¡TICO POR 99.000 (PERMANENCIA 12 MESES) | J34: On Line | N34: Activo | O34: PAGOS ON LINE / CLEZ PAY-99000.00 | P34: 45937.335 | Q34: 7777777 | R34: CLEZ | U34: Factura de Venta | W34: Facturado automaticamente por CLEZ PAY (Cron cobro suscripcion) Facturado automaticamente por CLEZ PAY (Cron cobro suscripcion) | X34: No | Y34: No | Z34: Renovado | AA34: Enviada | AB34: No | AC34: =IFERROR(VLOOKUP(C34,MigradosEfectivamente!B:B,1,FALSE),"No encontrado") -> No encontrado
A35: FPP-26893 | B35: MARIA ACOSTA | C35: 1102387884 | D35: JUNIN | E35: 3156416637 | F35: emariaacosta3572@gmail.com | G35: 89 | H35: Piedecuesta | I35: PLAN DEBITO AUTOMÃ¡TICO POR 89.000 (PERMANENCIA 12 MESES) | J35: On Line | N35: Activo | O35: PAGOS ON LINE / CLEZ PAY-89000.00 | P35: 45937.335 | Q35: 7777777 | R35: CLEZ | U35: Factura de Venta | W35: Facturado automaticamente por CLEZ PAY (Cron cobro suscripcion) Facturado automaticamente por CLEZ PAY (Cron cobro suscripcion) | X35: No | Y35: Si | Z35: Renovado | AA35: Enviada | AB35: No | AC35: =IFERROR(VLOOKUP(C35,MigradosEfectivamente!B:B,1,FALSE),"No encontrado") -> No encontrado
A36: FPP-26892 | B36: NIXON CASTELLANOS | C36: 1127337039 | D36: br la argentina | E36: 3042907313 | F36: nameltrltr@gmail.com | G36: 89 | H36: Piedecuesta | I36: PLAN DEBITO AUTOMÃ¡TICO POR 89.000 (PERMANENCIA 12 MESES) | J36: On Line | N36: Activo | O36: PAGOS ON LINE / CLEZ PAY-89000.00 | P36: 45937.334 | Q36: 7777777 | R36: CLEZ | U36: Factura de Venta | W36: Facturado automaticamente por CLEZ PAY (Cron cobro suscripcion) Facturado automaticamente por CLEZ PAY (Cron cobro suscripcion) | X36: No | Y36: Si | Z36: Renovado | AA36: Enviada | AB36: No | AC36: =IFERROR(VLOOKUP(C36,MigradosEfectivamente!B:B,1,FALSE),"No encontrado") -> 1127337039
A37: FPNS-30929 | B37: MAYRA ALEJANDRA PAEZ TRILLOS | C37: 1090452609 | D37: Cucuta | E37: 3156001478 - 3168376158 | F37: MAYRAPAEZ92@GMAIL.COM | G37: 349 | H37: Cucuta | I37: CLEZ 4 MESES DELUXE | J37: On Line | N37: Activo | O37: PAGOS ON LINE / CLEZ PAY-349000.00 | P37: 45937.198 | Q37: 7777777 | R37: CLEZ | U37: Factura de Venta | W37: Facturado automaticamente por CLEZ PAY Facturado automaticamente por CLEZ PAY | X37: No | Y37: Si | Z37: Recuperado | AA37: Enviada | AB37: No | AC37: =IFERROR(VLOOKUP(C37,MigradosEfectivamente!B:B,1,FALSE),"No encontrado") -> No encontrado
A38: FP-34282 | B38: JHON EDINSON SIERRA CORREDOR | C38: 1092334876 | D38: bucaramanga | E38: 3123682469 | F38: jerjhon55@gmail.com | G38: 89 | H38: Provenza | I38: PLAN DEBITO AUTOMÃ¡TICO POR 99.000 (PERMANENCIA 12 MESES) | J38: On Line | N38: Activo | O38: PAGOS ON LINE / CLEZ PAY-89000.00 | P38: 45936.879 | Q38: 7777777 | R38: CLEZ | U38: Factura de Venta | W38: Facturado automaticamente por CLEZ PAY (Cron cobro suscripcion) Facturado automaticamente por CLEZ PAY (Cron cobro suscripcion) | X38: No | Y38: No | Z38: Renovado | AA38: Enviada | AB38: No | AC38: =IFERROR(VLOOKUP(C38,MigradosEfectivamente!B:B,1,FALSE),"No encontrado") -> No encontrado
A39: PR-1703 | B39: LEIDIS TRINIDAD BAQUERO DEL TORO | C39: 1193598878 | D39: Prado | E39: 3117999832 | F39: leidisbaquero33@gmail.com | G39: 89 | H39: El Prado | I39: PLAN DEBITO AUTOMÃ¡TICO POR 89.000 (PERMANENCIA 12 MESES) | J39: On Line | N39: Activo | O39: PAGOS ON LINE / CLEZ PAY-89000.00 | P39: 45936.875 | Q39: 7777777 | R39: CLEZ | U39: Factura de Venta | W39: Facturado automaticamente por CLEZ PAY (Cron cobro suscripcion) Facturado automaticamente por CLEZ PAY (Cron cobro suscripcion) | X39: No | Y39: Si | Z39: Renovado | AA39: Enviada | AB39: No | AC39: =IFERROR(VLOOKUP(C39,MigradosEfectivamente!B:B,1,FALSE),"No encontrado") -> No encontrado
A40: CB-8959 | B40: MARIA FERNANDA MOYA JIMENEZ | C40: 1098745697 | D40: BUCARAMANGA | E40: 3172917358 | F40: Mfmoya893@gmail.com | G40: 89 | H40: Cabecera | I40: PLAN DEBITO AUTOMÃ¡TICO POR 89.000 (PERMANENCIA 12 MESES) | J40: On Line | N40: Activo | O40: PAGOS ON LINE / CLEZ PAY-89000.00 | P40: 45936.875 | Q40: 7777777 | R40: CLEZ | U40: Factura de Venta | W40: Facturado automaticamente por CLEZ PAY (Cron cobro suscripcion) Facturado automaticamente por CLEZ PAY (Cron cobro suscripcion) | X40: No | Y40: Si | Z40: Renovado | AA40: No enviada | AB40: No | AC40: =IFERROR(VLOOKUP(C40,MigradosEfectivamente!B:B,1,FALSE),"No encontrado") -> No encontrado
...

Sheet MigradosEfectivamente
A1: IdAfiliado | B1: DocumentoAfiliado | C1: idTipoDocumento | D1: NombreAfiliado | E1: ApellidoAfiliado | F1: CelularAfiliado | G1: EmailAfiliado | H1: ClaveAfiliado | I1: DireccionAfiliado | J1: idCiudadAfiliado | K1: FechaNacAfiliado | L1: FotoAfiliado | M1: idGenero | N1: idSede | O1: idEstadoCivilAfiliado | P1: idEmpresaAfil | Q1: idProfesion | R1: idEPS | S1: ResponsableAfiliado | T1: Parentesco | U1: ContactoAfiliado | V1: idUsuario | W1: EstadoAfiliado | X1: FechaAfiliacion | Y1: ProcesoActFecNac | Z1: ObservacionesParQ | AA1: Columna1
A2: 2135 | B2: 1098682492 | C2: 3 | D2: Daniel Felipe | E2: Quijano Dominguez | F2: 3164353062 | G2: quijanodominguezdanielfelipe@gmail.com | H2: \N | I2: \N | J2: 1 | K2: 39483 | L2: \N | M2: 1 | N2: 10 | O2: \N | P2: \N | Q2: \N | R2: \N | S2: \N | T2: \N | U2: \N | V2: \N | W2: Pendiente | X2: 45916 | Y2: 0 | Z2: \N | AA2: =IFERROR(VLOOKUP(B2,BD_Clez_Premigracion!C:C,1,FALSE),"No encontrado") -> 1098682492
A3: 2136 | B3: 1030542921 | C3: 1 | D3: VALENTINA | E3: SAAVEDRA HOYOS | F3: 3196218540 | G3: valentinahoyos77@gmail.com | H3: \N | I3: \N | J3: 1 | K3: 38041 | L3: \N | M3: 2 | N3: 10 | O3: \N | P3: \N | Q3: \N | R3: \N | S3: \N | T3: \N | U3: \N | V3: \N | W3: Pendiente | X3: 45916 | Y3: 0 | Z3: \N | AA3: =IFERROR(VLOOKUP(B3,BD_Clez_Premigracion!C:C,1,FALSE),"No encontrado") -> 1030542921
A4: 2137 | B4: 1098649193 | C4: 1 | D4: ALEXANDRA | E4: GELVEZ ROJAS | F4: 3102944662 | G4: Alexandrag54@hotmail.com | H4: \N | I4: \N | J4: 1 | K4: 32180 | L4: \N | M4: 2 | N4: 8 | O4: \N | P4: \N | Q4: \N | R4: \N | S4: \N | T4: \N | U4: \N | V4: \N | W4: Pendiente | X4: 45916 | Y4: 0 | Z4: \N | AA4: =IFERROR(VLOOKUP(B4,BD_Clez_Premigracion!C:C,1,FALSE),"No encontrado") -> 1098649193
A5: 2138 | B5: 1098635512 | C5: 1 | D5: SANTIAGO SNEIDER | E5: VILLAMIZAR LOPEZ | F5: 3169075502 | G5: santiagovillamizar500@gmail.com | H5: \N | I5: \N | J5: 1 | K5: 38459 | L5: \N | M5: 1 | N5: 10 | O5: \N | P5: \N | Q5: \N | R5: \N | S5: \N | T5: \N | U5: \N | V5: \N | W5: Pendiente | X5: 45916 | Y5: 0 | Z5: \N | AA5: =IFERROR(VLOOKUP(B5,BD_Clez_Premigracion!C:C,1,FALSE),"No encontrado") -> No encontrado
A6: 2144 | B6: 1098800251 | C6: 1 | D6: ALEJANDRA | E6: PINILLA MELENDEZ | F6: 3178539153 | G6: alejandrapinilla_97@hotmail.com | H6: \N | I6: \N | J6: 1 | K6: 35684 | L6: \N | M6: 2 | N6: 8 | O6: \N | P6: \N | Q6: \N | R6: \N | S6: \N | T6: \N | U6: \N | V6: \N | W6: Pendiente | X6: 45917 | Y6: 0 | Z6: \N | AA6: =IFERROR(VLOOKUP(B6,BD_Clez_Premigracion!C:C,1,FALSE),"No encontrado") -> No encontrado
A7: 2148 | B7: 1140831066 | C7: 1 | D7: ERIC DANIEL | E7: RIVALDO CORONELL | F7: 3115430198 | G7: ericrivaldocoronell@gmail.com | H7: \N | I7: \N | J7: 1 | K7: 33045 | L7: \N | M7: 1 | N7: 8 | O7: \N | P7: \N | Q7: \N | R7: \N | S7: \N | T7: \N | U7: \N | V7: \N | W7: Pendiente | X7: 45917 | Y7: 0 | Z7: \N | AA7: =IFERROR(VLOOKUP(B7,BD_Clez_Premigracion!C:C,1,FALSE),"No encontrado") -> No encontrado
A8: 2152 | B8: 1097182426 | C8: 1 | D8: PAULA ANDREA | E8: AGUIRRE RINCON | F8: 3219316506 | G8: andreitaaguirre08@gmail.com | H8: \N | I8: \N | J8: 1 | K8: 38204 | L8: \N | M8: 2 | N8: 8 | O8: \N | P8: \N | Q8: \N | R8: \N | S8: \N | T8: \N | U8: \N | V8: \N | W8: Pendiente | X8: 45917 | Y8: 0 | Z8: \N | AA8: =IFERROR(VLOOKUP(B8,BD_Clez_Premigracion!C:C,1,FALSE),"No encontrado") -> No encontrado
A9: 2139 | B9: 5081664 | C9: 6 | D9: Yayre | E9: Quintero Sánchez | F9: 3505347893 | G9: yayrels@gmail.com | H9: \N | I9: \N | J9: 1 | K9: 35466 | L9: \N | M9: 2 | N9: 10 | O9: \N | P9: \N | Q9: \N | R9: \N | S9: \N | T9: \N | U9: \N | V9: \N | W9: Activo | X9: 45916 | Y9: 0 | Z9: \N | AA9: =IFERROR(VLOOKUP(B9,BD_Clez_Premigracion!C:C,1,FALSE),"No encontrado") -> No encontrado
A10: 2153 | B10: 1193374427 | C10: 1 | D10: LAURA CAMILA | E10: RANGEL CARDENAS | F10: 3197647367 | G10: laurangcard@hotmail.com | H10: \N | I10: \N | J10: 4 | K10: 36909 | L10: \N | M10: 2 | N10: 6 | O10: \N | P10: \N | Q10: \N | R10: \N | S10: \N | T10: \N | U10: \N | V10: \N | W10: Pendiente | X10: 45918 | Y10: 0 | Z10: \N | AA10: =IFERROR(VLOOKUP(B10,BD_Clez_Premigracion!C:C,1,FALSE),"No encontrado") -> 1193374427
A11: 2156 | B11: 1093777011 | C11: 1 | D11: CARLOS HUMBERTO | E11: FIGUEROA ANGARITA | F11: 3224020128 | G11: Carlosfangarita001@gmail.com | H11: \N | I11: \N | J11: 4 | K11: 34735 | L11: \N | M11: 1 | N11: 6 | O11: \N | P11: \N | Q11: \N | R11: \N | S11: \N | T11: \N | U11: \N | V11: \N | W11: Pendiente | X11: 45918 | Y11: 0 | Z11: \N | AA11: =IFERROR(VLOOKUP(B11,BD_Clez_Premigracion!C:C,1,FALSE),"No encontrado") -> No encontrado
A12: 2157 | B12: 1102714541 | C12: 1 | D12: JHOAN JOSE | E12: TOLEDO VERA | F12: 3153186367 | G12: Jjosetoledo1991@gmail.com | H12: \N | I12: \N | J12: 1 | K12: 33323 | L12: \N | M12: 1 | N12: 2 | O12: \N | P12: \N | Q12: \N | R12: \N | S12: \N | T12: \N | U12: \N | V12: \N | W12: Pendiente | X12: 45918 | Y12: 0 | Z12: \N | AA12: =IFERROR(VLOOKUP(B12,BD_Clez_Premigracion!C:C,1,FALSE),"No encontrado") -> 1102714541
A13: 2158 | B13: 1098822746 | C13: 1 | D13: SEBASTIAN | E13: LOPEZ RUEDA | F13: 3187252767 | G13: Sebaslopezru7@gmail.com | H13: \N | I13: \N | J13: 1 | K13: 36375 | L13: \N | M13: 1 | N13: 2 | O13: \N | P13: \N | Q13: \N | R13: \N | S13: \N | T13: \N | U13: \N | V13: \N | W13: Pendiente | X13: 45918 | Y13: 0 | Z13: \N | AA13: =IFERROR(VLOOKUP(B13,BD_Clez_Premigracion!C:C,1,FALSE),"No encontrado") -> No encontrado
... A23: 2145 | B23: 108797587 | C23: 4 | D23: José Andrés | E23: Vera peña | F23: 3204669676 | G23: Veraandresoficial@gmail.com | H23: \N | I23: \N | J23: 1 | K23: 35553 | L23: \N | M23: 1 | N23: 8 | O23: \N | P23: \N | Q23: \N | R23: \N | S23: \N | T23: \N | U23: \N | V23: \N | W23: Pendiente | X23: 45917 | Y23: 0 | Z23: \N | AA23: =IFERROR(VLOOKUP(B23,BD_Clez_Premigracion!C:C,1,FALSE),"No encontrado") -> No encontrado
A24: 2176 | B24: 1005372165 | C24: 1 | D24: ANA CAMILA | E24: CAAMAÑO DIAZ | F24: 3124778011 | G24: camilacd0926@gmail.com | H24: \N | I24: Calle 8 # 11-47 | J24: 2 | K24: 37020 | L24: \N | M24: 2 | N24: 3 | O24: \N | P24: \N | Q24: \N | R24: 4 | S24: Samuel Caamaño | T24: Hermano/a | U24: 3172798847 | V24: \N | W24: Activo | X24: 45921 | Y24: 0 | AA24: =IFERROR(VLOOKUP(B24,BD_Clez_Premigracion!C:C,1,FALSE),"No encontrado") -> No encontrado
A25: 2177 | B25: 1102376249 | C25: 1 | D25: Katherine | E25: Rodriguez santiago | F25: 3117076240 | G25: Kathesantiago29@gmail.com | H25: \N | I25: \N | J25: 3 | K25: 34728 | L25: \N | M25: 2 | N25: 5 | O25: \N | P25: \N | Q25: \N | R25: \N | S25: \N | T25: \N | U25: \N | V25: \N | W25: Pendiente | X25: 45921 | Y25: 0 | Z25: \N | AA25: =IFERROR(VLOOKUP(B25,BD_Clez_Premigracion!C:C,1,FALSE),"No encontrado") -> No encontrado
A26: 2141 | B26: 1095831653 | C26: 1 | D26: ANGIE STEFANIA | E26: QUIJANO PLATA | F26: 3144438697 | G26: tatisplata9@gmail.com | H26: \N | I26: \N | J26: 1 | K26: 35388 | L26: \N | M26: 2 | N26: 2 | O26: \N | P26: \N | Q26: \N | R26: \N | S26: \N | T26: \N | U26: \N | V26: \N | W26: Pendiente | X26: 45916 | Y26: 0 | Z26: \N | AA26: =IFERROR(VLOOKUP(B26,BD_Clez_Premigracion!C:C,1,FALSE),"No encontrado") -> 1095831653
A27: 2178 | B27: 1092386369 | C27: 1 | D27: EDUARDO ANDRES | E27: RAMIREZ CARDENAS | F27: 3142927674 | G27: Eduardoandres_1998@hotmail.com | H27: \N | I27: Villas de Montecarlo casa C10 | J27: \N | K27: 35985 | L27: \N | M27: 1 | N27: 4 | O27: \N | P27: \N | Q27: \N | R27: 1 | S27: Luz cardneas | T27: Padre/Madre | U27: 3124528163 | V27: \N | W27: Activo | X27: 45922 | Y27: 0 | AA27: =IFERROR(VLOOKUP(B27,BD_Clez_Premigracion!C:C,1,FALSE),"No encontrado") -> No encontrado
A28: 2179 | B28: 1148221342 | C28: 1 | D28: KEVIN EDUARDO | E28: ALVAREZ DIAZ | F28: 3028050235 | G28: kevtraderve@gmail.com | H28: \N | I28: \N | J28: \N | K28: 36577 | L28: \N | M28: 1 | N28: 6 | O28: \N | P28: \N | Q28: \N | R28: \N | S28: \N | T28: \N | U28: \N | V28: \N | W28: Pendiente | X28: 45922 | Y28: 0 | Z28: \N | AA28: =IFERROR(VLOOKUP(B28,BD_Clez_Premigracion!C:C,1,FALSE),"No encontrado") -> No encontrado
A29: 2180 | B29: 1005257154 | C29: 1 | D29: GABRIEL ALEJANDRO | E29: VELA MARTINEZ | F29: 3150675863 | G29: gabriel.alejandro125@gmail.com | H29: \N | I29: \N | J29: \N | K29: 37128 | L29: \N | M29: 1 | N29: 1 | O29: \N | P29: \N | Q29: \N | R29: \N | S29: \N | T29: \N | U29: \N | V29: \N | W29: Pendiente | X29: 45922 | Y29: 0 | Z29: \N | AA29: =IFERROR(VLOOKUP(B29,BD_Clez_Premigracion!C:C,1,FALSE),"No encontrado") -> 1005257154
A30: 2181 | B30: 1093854460 | C30: 1 | D30: ERIC SAMUEL | E30: SUAREZ NUÑEZ | F30: 3028502200 | G30: Yanamensajera@hotmail.com | H30: \N | I30: \N | J30: \N | K30: 38225 | L30: \N | M30: 1 | N30: 6 | O30: \N | P30: \N | Q30: \N | R30: \N | S30: \N | T30: \N | U30: \N | V30: \N | W30: Pendiente | X30: 45922 | Y30: 0 | Z30: \N | AA30: =IFERROR(VLOOKUP(B30,BD_Clez_Premigracion!C:C,1,FALSE),"No encontrado") -> No encontrado
A31: 2182 | B31: 1126424740 | C31: 1 | D31: PAULO CESAR | E31: RINCON NAVARRO | F31: 3228742598 | G31: paulorinconpr88@gmail.com | H31: \N | I31: \N | J31: \N | K31: 26839 | L31: \N | M31: 1 | N31: 4 | O31: \N | P31: \N | Q31: \N | R31: \N | S31: \N | T31: \N | U31: \N | V31: \N | W31: Pendiente | X31: 45922 | Y31: 0 | Z31: \N | AA31: =IFERROR(VLOOKUP(B31,BD_Clez_Premigracion!C:C,1,FALSE),"No encontrado") -> No encontrado
A32: 2188 | B32: 1095837324 | C32: 1 | D32: Jefferson Julian | E32: Gonzalez Bueno | F32: 3153795088 | G32: Julian1327gonzalez@gmail.com | H32: \N | I32: \N | J32: \N | K32: 35867 | L32: \N | M32: 1 | N32: 5 | O32: \N | P32: \N | Q32: \N | R32: \N | S32: \N | T32: \N | U32: \N | V32: \N | W32: Pendiente | X32: 45923 | Y32: 0 | Z32: \N | AA32: =IFERROR(VLOOKUP(B32,BD_Clez_Premigracion!C:C,1,FALSE),"No encontrado") -> No encontrado
A33: 2185 | B33: 1098766559 | C33: 1 | D33: KAREN ALICIA | E33: PABON RIATIGA | F33: 3212371879 | G33: aliciapabon1994@gmail.com | H33: \N | I33: \N | J33: \N | K33: 34669 | L33: \N | M33: 2 | N33: 8 | O33: \N | P33: \N | Q33: \N | R33: \N | S33: \N | T33: \N | U33: \N | V33: \N | W33: Pendiente | X33: 45922 | Y33: 0 | Z33: \N | AA33: =IFERROR(VLOOKUP(B33,BD_Clez_Premigracion!C:C,1,FALSE),"No encontrado") -> No encontrado
A34: 2184 | B34: 1005199841 | C34: 1 | D34: MICHELL KATHERINE | E34: SOLANO GELVEZ | F34: 3181652462 | G34: kgelvez2002@gmail.com | H34: \N | I34: \N | J34: \N | K34: 37447 | L34: \N | M34: 2 | N34: 1 | O34: \N | P34: \N | Q34: \N | R34: \N | S34: \N | T34: \N | U34: \N | V34: \N | W34: Pendiente | X34: 45922 | Y34: 0 | Z34: \N | AA34: =IFERROR(VLOOKUP(B34,BD_Clez_Premigracion!C:C,1,FALSE),"No encontrado") -> 1005199841
A35: 2189 | B35: 1098805509 | C35: 1 | D35: JUAN JOSE | E35: DUARTE RODRIGUEZ | F35: 3132298289 | G35: duarte9701@gmail.com | H35: \N | I35: \N | J35: \N | K35: 35704 | L35: \N | M35: 1 | N35: 6 | O35: \N | P35: \N | Q35: \N | R35: \N | S35: \N | T35: \N | U35: \N | V35: \N | W35: Pendiente | X35: 45923 | Y35: 0 | Z35: \N | AA35: =IFERROR(VLOOKUP(B35,BD_Clez_Premigracion!C:C,1,FALSE),"No encontrado") -> No encontrado
A36: 2191 | B36: 22798614 | C36: 1 | D36: HILDEGARDE LUCILA | E36: CORREAL RUEDA | F36: 3168950806 | G36: hildegarde1979@hotmail.com | H36: \N | I36: \N | J36: \N | K36: 28974 | L36: \N | M36: 2 | N36: 10 | O36: \N | P36: \N | Q36: \N | R36: \N | S36: \N | T36: \N | U36: \N | V36: \N | W36: Pendiente | X36: 45923 | Y36: 0 | Z36: \N | AA36: =IFERROR(VLOOKUP(B36,BD_Clez_Premigracion!C:C,1,FALSE),"No encontrado") -> No encontrado
A37: 2192 | B37: 1006372165 | C37: 1 | D37: Ana Camila | E37: Caamaño Diaz | F37: 3124778011 | G37: camilacd0926@gmail.com | H37: \N | I37: \N | J37: \N | K37: 37020 | L37: \N | M37: 2 | N37: 3 | O37: \N | P37: \N | Q37: \N | R37: \N | S37: \N | T37: \N | U37: \N | V37: \N | W37: Pendiente | X37: 45924 | Y37: 0 | Z37: \N | AA37: =IFERROR(VLOOKUP(B37,BD_Clez_Premigracion!C:C,1,FALSE),"No encontrado") -> No encontrado
A38: 2193 | B38: 1095949447 | C38: 1 | D38: EDER FABIAN | E38: NIETO LEON | F38: 3177227375 | G38: ederfabiannieto@gmail.com | H38: \N | I38: \N | J38: \N | K38: 35658 | L38: \N | M38: 1 | N38: 8 | O38: \N | P38: \N | Q38: \N | R38: \N | S38: \N | T38: \N | U38: \N | V38: \N | W38: Pendiente | X38: 45924 | Y38: 0 | Z38: \N | AA38: =IFERROR(VLOOKUP(B38,BD_Clez_Premigracion!C:C,1,FALSE),"No encontrado") -> 1095949447
A39: 2196 | B39: 1091354733 | C39: 1 | D39: MARIA FERNANDA | E39: ECHEVERRI JOYA | F39: 3188213670 | G39: mafe.ej1823@gmail.com | H39: \N | I39: \N | J39: \N | K39: 38429 | L39: \N | M39: 2 | N39: 6 | O39: \N | P39: \N | Q39: \N | R39: \N | S39: \N | T39: \N | U39: \N | V39: \N | W39: Pendiente | X39: 45924 | Y39: 0 | Z39: \N | AA39: =IFERROR(VLOOKUP(B39,BD_Clez_Premigracion!C:C,1,FALSE),"No encontrado") -> 1091354733
... A61: 2231 | B61: 1095300596 | C61: 1 | D61: Sirley | E61: Ardila | F61: 3185197630 | G61: ardilabautistasirley@gmail.com | H61: \N | I61: \N | J61: \N | K61: 38365 | L61: \N | M61: 2 | N61: 2 | O61: \N | P61: \N | Q61: \N | R61: \N | S61: \N | T61: \N | U61: \N | V61: \N | W61: Pendiente | X61: 45929 | Y61: 0 | Z61: \N | AA61: =IFERROR(VLOOKUP(B61,BD_Clez_Premigracion!C:C,1,FALSE),"No encontrado") -> 1095300596
A62: 2232 | B62: 1098718284 | C62: 1 | D62: JORGE ANDRES | E62: BAUTISTA MENDEZ | F62: 3153049735 | G62: joanbamen23@gmail.com | H62: \N | I62: Avenida Búcaros #60-319 torocoma T4 101 | J62: \N | K62: 33657 | L62: \N | M62: 1 | N62: 10 | O62: \N | P62: \N | Q62: \N | R62: 6 | S62: Mongui Muñoz | T62: Padre/Madre | U62: 3168795456 | V62: \N | W62: Activo | X62: 45929 | Y62: 0 | AA62: =IFERROR(VLOOKUP(B62,BD_Clez_Premigracion!C:C,1,FALSE),"No encontrado") -> No encontrado
A63: 2229 | B63: 3079306 | C63: 6 | D63: Manuel Alejandro | E63: Pérez contreras | F63: 3027028560 | G63: alejandrocontreras1932@gmail.com | H63: \N | I63: \N | J63: \N | K63: 33467 | L63: \N | M63: 1 | N63: 1 | O63: \N | P63: \N | Q63: \N | R63: \N | S63: \N | T63: \N | U63: \N | V63: \N | W63: Pendiente | X63: 45929 | Y63: 0 | Z63: \N | AA63: =IFERROR(VLOOKUP(B63,BD_Clez_Premigracion!C:C,1,FALSE),"No encontrado") -> 3079306
A64: 2225 | B64: 1127665592 | C64: 1 | D64: NADIA KARINA | E64: GUERRERO PAZ | F64: 3202888083 | G64: Nadiakarina1085@gmail.com | H64: \N | I64: \N | J64: \N | K64: 31333 | L64: \N | M64: 2 | N64: 4 | O64: \N | P64: \N | Q64: \N | R64: \N | S64: \N | T64: \N | U64: \N | V64: \N | W64: Pendiente | X64: 45929 | Y64: 0 | Z64: \N | AA64: =IFERROR(VLOOKUP(B64,BD_Clez_Premigracion!C:C,1,FALSE),"No encontrado") -> No encontrado
A65: 2207 | B65: 1098812062 | C65: 1 | D65: IVONNE ANDREA | E65: RUEDA VASQUEZ | F65: 3219566017 | G65: andrearueda127@gmail.com | H65: \N | I65: \N | J65: \N | K65: 36068 | L65: \N | M65: 2 | N65: 10 | O65: \N | P65: \N | Q65: \N | R65: \N | S65: \N | T65: \N | U65: \N | V65: \N | W65: Pendiente | X65: 45925 | Y65: 0 | Z65: \N | AA65: =IFERROR(VLOOKUP(B65,BD_Clez_Premigracion!C:C,1,FALSE),"No encontrado") -> 1098812062
A66: 2233 | B66: 1192716330 | C66: 1 | D66: DIEGO EDSON | E66: URIBE SALAZAR | F66: 3123551936 | G66: Diego042024@gmail.com | H66: \N | I66: \N | J66: \N | K66: 37366 | L66: \N | M66: 1 | N66: 4 | O66: \N | P66: \N | Q66: \N | R66: \N | S66: \N | T66: \N | U66: \N | V66: \N | W66: Pendiente | X66: 45929 | Y66: 0 | Z66: \N | AA66: =IFERROR(VLOOKUP(B66,BD_Clez_Premigracion!C:C,1,FALSE),"No encontrado") -> 1192716330
A67: 2214 | B67: 1090521204 | C67: 1 | D67: JULIETH KATHERINE | E67: VILLAMIZAR OSORIO | F67: 3217134813 | G67: Yulipdcdesv@gmail.com | H67: \N | I67: \N | J67: \N | K67: 35949 | L67: \N | M67: 2 | N67: 2 | O67: \N | P67: \N | Q67: \N | R67: \N | S67: \N | T67: \N | U67: \N | V67: \N | W67: Pendiente | X67: 45925 | Y67: 0 | Z67: \N | AA67: =IFERROR(VLOOKUP(B67,BD_Clez_Premigracion!C:C,1,FALSE),"No encontrado") -> 1090521204
A68: 2234 | B68: 1098070689 | C68: 1 | D68: DANIEL HERNANDO | E68: LOPEZ VEGA | F68: 3107907445 | G68: Danielopesitos@gmail.com | H68: \N | I68: Calle 50#22-87 | J68: \N | K68: 38289 | L68: \N | M68: 1 | N68: 2 | O68: \N | P68: \N | Q68: \N | R68: 3 | S68: Hernando Lopez | T68: Padre/Madre | U68: 3212570548 | V68: \N | W68: Activo | X68: 45929 | Y68: 0 | AA68: =IFERROR(VLOOKUP(B68,BD_Clez_Premigracion!C:C,1,FALSE),"No encontrado") -> No encontrado
A69: 2235 | B69: 1098819918 | C69: 1 | D69: ANDRY YURANY | E69: ANDRADE SANDOVAL | F69: 3223223953 | G69: Andryur05@gmail.com | H69: \N | I69: Carrera 18#8a-30 | J69: \N | K69: 36316 | L69: \N | M69: 2 | N69: 2 | O69: \N | P69: \N | Q69: \N | R69: 1 | S69: Daniel | T69: Esposo/a | U69: 3107907445 | V69: \N | W69: Activo | X69: 45929 | Y69: 0 | AA69: =IFERROR(VLOOKUP(B69,BD_Clez_Premigracion!C:C,1,FALSE),"No encontrado") -> No encontrado
A70: 2236 | B70: 1044607327 | C70: 1 | D70: ISABEL SOFIA | E70: RUEDA PORRAS | F70: 3043322841 | G70: Isabelsrueda23@gmail.com | H70: \N | I70: TV 154 #157-65 | J70: \N | K70: 38344 | L70: \N | M70: 2 | N70: 3 | O70: \N | P70: \N | Q70: \N | R70: 7 | S70: Shirley porras | T70: Padre/Madre | U70: 3155130595 | V70: \N | W70: Activo | X70: 45929 | Y70: 0 | AA70: =IFERROR(VLOOKUP(B70,BD_Clez_Premigracion!C:C,1,FALSE),"No encontrado") -> No encontrado
...

Sheet AfiliadosRecurrentesNuevos
A1: IdAfiliado | B1: DocumentoAfiliado | C1: idTipoDocumento | D1: NombreAfiliado | E1: ApellidoAfiliado | F1: CelularAfiliado | G1: EmailAfiliado | H1: ClaveAfiliado | I1: DireccionAfiliado | J1: idCiudadAfiliado | K1: FechaNacAfiliado | L1: FotoAfiliado | M1: idGenero | N1: idSede | O1: idEstadoCivilAfiliado | P1: idEmpresaAfil | Q1: idProfesion | R1: idEPS | S1: ResponsableAfiliado | T1: Parentesco | U1: ContactoAfiliado | V1: idUsuario | W1: EstadoAfiliado | X1: FechaAfiliacion | Y1: ProcesoActFecNac | Z1: ObservacionesParQ | AA1: idPlan
A2: 2169 | B2: 1098608981 | C2: 1 | D2: JONATHAN DAVID | E2: RODRIGUEZ CONDE | F2: 3213472473 | G2: jonathan.rodriguez2941@gmail.com | H2: \N | I2: \N | J2: 1 | K2: 38034 | L2: \N | M2: 1 | N2: 2 | O2: \N | P2: \N | Q2: \N | R2: \N | S2: \N | T2: \N | U2: \N | V2: \N | W2: Pendiente | X2: 45919 | Y2: 0 | Z2: \N | AA2: 1
A3: 2178 | B3: 1092386369 | C3: 1 | D3: EDUARDO ANDRES | E3: RAMIREZ CARDENAS | F3: 3142927674 | G3: Eduardoandres_1998@hotmail.com | H3: \N | I3: Villas de Montecarlo casa C10 | J3: \N | K3: 35985 | L3: \N | M3: 1 | N3: 4 | O3: \N | P3: \N | Q3: \N | R3: 1 | S3: Luz cardneas | T3: Padre/Madre | U3: 3124528163 | V3: \N | W3: Activo | X3: 45922 | Y3: 0 | AA3: 1
A4: 2182 | B4: 1126424740 | C4: 1 | D4: PAULO CESAR | E4: RINCON NAVARRO | F4: 3228742598 | G4: paulorinconpr88@gmail.com | H4: \N | I4: \N | J4: \N | K4: 26839 | L4: \N | M4: 1 | N4: 4 | O4: \N | P4: \N | Q4: \N | R4: \N | S4: \N | T4: \N | U4: \N | V4: \N | W4: Pendiente | X4: 45922 | Y4: 0 | Z4: \N | AA4: 1
A5: 2185 | B5: 1098766559 | C5: 1 | D5: KAREN ALICIA | E5: PABON RIATIGA | F5: 3212371879 | G5: aliciapabon1994@gmail.com | H5: \N | I5: \N | J5: \N | K5: 34669 | L5: \N | M5: 2 | N5: 8 | O5: \N | P5: \N | Q5: \N | R5: \N | S5: \N | T5: \N | U5: \N | V5: \N | W5: Pendiente | X5: 45922 | Y5: 0 | Z5: \N | AA5: 1
A6: 2197 | B6: 1095944090 | C6: 1 | D6: TATIANA ANDREA | E6: SILVA CARDENAS | F6: 3132497055 | G6: Andrea_silva31@hotmail.com | H6: \N | I6: \N | J6: \N | K6: 35216 | L6: \N | M6: 2 | N6: 8 | O6: \N | P6: \N | Q6: \N | R6: \N | S6: \N | T6: \N | U6: \N | V6: \N | W6: Pendiente | X6: 45924 | Y6: 0 | Z6: \N | AA6: 1
A7: 2217 | B7: 1007398638 | C7: 1 | D7: BEDER MOISES | E7: DURAN DUQUE | F7: 3156115465 | G7: duranbeder06@gmail.com | H7: \N | I7: \N | J7: \N | K7: 36562 | L7: \N | M7: 1 | N7: 2 | O7: \N | P7: \N | Q7: \N | R7: \N | S7: \N | T7: \N | U7: \N | V7: \N | W7: Pendiente | X7: 45926 | Y7: 0 | Z7: \N | AA7: 1
A8: 2223 | B8: 1005281651 | C8: 1 | D8: NICOLAS FELIPE | E8: MURILLO ESTEBAN | F8: 3025118581 | G8: nicolasfoxin@gmail.com | H8: \N | I8: \N | J8: \N | K8: 36865 | L8: \N | M8: 1 | N8: 2 | O8: \N | P8: \N | Q8: \N | R8: \N | S8: \N | T8: \N | U8: \N | V8: \N | W8: Pendiente | X8: 45927 | Y8: 0 | Z8: \N | AA8: 1
A9: 2232 | B9: 1098718284 | C9: 1 | D9: JORGE ANDRES | E9: BAUTISTA MENDEZ | F9: 3153049735 | G9: joanbamen23@gmail.com | H9: \N | I9: Avenida Búcaros #60-319 torocoma T4 101 | J9: \N | K9: 33657 | L9: \N | M9: 1 | N9: 10 | O9: \N | P9: \N | Q9: \N | R9: 6 | S9: Mongui Muñoz | T9: Padre/Madre | U9: 3168795456 | V9: \N | W9: Activo | X9: 45929 | Y9: 0 | AA9: 18
A10: 2234 | B10: 1098070689 | C10: 1 | D10: DANIEL HERNANDO | E10: LOPEZ VEGA | F10: 3107907445 | G10: Danielopesitos@gmail.com | H10: \N | I10: Calle 50#22-87 | J10: \N | K10: 38289 | L10: \N | M10: 1 | N10: 2 | O10: \N | P10: \N | Q10: \N | R10: 3 | S10: Hernando Lopez | T10: Padre/Madre | U10: 3212570548 | V10: \N | W10: Activo | X10: 45929 | Y10: 0 | AA10: 1
A11: 2235 | B11: 1098819918 | C11: 1 | D11: ANDRY YURANY | E11: ANDRADE SANDOVAL | F11: 3223223953 | G11: Andryur05@gmail.com | H11: \N | I11: Carrera 18#8a-30 | J11: \N | K11: 36316 | L11: \N | M11: 2 | N11: 2 | O11: \N | P11: \N | Q11: \N | R11: 1 | S11: Daniel | T11: Esposo/a | U11: 3107907445 | V11: \N | W11: Activo | X11: 45929 | Y11: 0 | AA11: 1
A12: 2236 | B12: 1044607327 | C12: 1 | D12: ISABEL SOFIA | E12: RUEDA PORRAS | F12: 3043322841 | G12: Isabelsrueda23@gmail.com | H12: \N | I12: TV 154 #157-65 | J12: \N | K12: 38344 | L12: \N | M12: 2 | N12: 3 | O12: \N | P12: \N | Q12: \N | R12: 7 | S12: Shirley porras | T12: Padre/Madre | U12: 3155130595 | V12: \N | W12: Activo | X12: 45929 | Y12: 0 | AA12: 1
A13: 2237 | B13: 1102361317 | C13: 3 | D13: Miguel Angel | E13: Torres Martinez | F13: 3006043949 | G13: miguelangeltorresmartinez07@gmail.com | H13: \N | I13: Cr 15 # 18-70 | J13: \N | K13: 39329 | L13: \N | M13: 1 | N13: 5 | O13: \N | P13: \N | Q13: \N | R13: 25 | S13: Mary luz Martínez castro | T13: Padre/Madre | U13: 3144219919 | V13: \N | W13: Activo | X13: 45929 | Y13: 0 | AA13: 1
A14: 2238 | B14: 1094267818 | C14: 1 | D14: Sair Alberto | E14: Pineda Gamboa | F14: 3016218873 | G14: sairalberto@gmail.com | H14: \N | I14: Callejas Torres | J14: \N | K14: 33565 | L14: \N | M14: 1 | N14: 4 | O14: \N | P14: \N | Q14: \N | R14: 7 | S14: Katherin Caceres | T14: Esposo/a | U14: 3168294669 | V14: \N | W14: Activo | X14: 45929 | Y14: 0 | AA14: 19
A15: 2250 | B15: 1076666956 | C15: 1 | D15: BRAYAN STIVEN | E15: RODRIGUEZ RODRIGUEZ | F15: 3204782802 | G15: brayansrodrig@gmail.com | H15: \N | I15: \N | J15: \N | K15: 35753 | L15: \N | M15: 1 | N15: 6 | O15: \N | P15: \N | Q15: \N | R15: \N | S15: \N | T15: \N | U15: \N | V15: \N | W15: Pendiente | X15: 45930 | Y15: 0 | Z15: \N | AA15: 19
A16: 2242 | B16: 1005282516 | C16: 1 | D16: ANGIE CRISTINA | E16: LOZANO MOGOLLON | F16: 3163220791 | G16: cristinangie09@gmail.com | H16: \N | I16: D | J16: \N | K16: 37873 | L16: \N | M16: 2 | N16: 3 | O16: \N | P16: \N | Q16: \N | R16: 9 | S16: Esperanza Mogollón Chaparro | T16: Padre/Madre | U16: 3152841584 | V16: \N | W16: Activo | X16: 45930 | Y16: 0 | AA16: 1
A17: 2255 | B17: 32175631 | C17: 2 | D17: Angel | E17: Guillén | F17: 3166370293 | G17: angeloguillen85@gmail.com | H17: \N | I17: \N | J17: \N | K17: 38602 | L17: \N | M17: 1 | N17: 10 | O17: \N | P17: \N | Q17: \N | R17: \N | S17: \N | T17: \N | U17: \N | V17: \N | W17: Pendiente | X17: 45930 | Y17: 0 | Z17: \N | AA17: 18
A18: 2256 | B18: 1098073585 | C18: 3 | D18: Sara | E18: Otalora bohorquez | F18: 3108897521 | G18: Otalorasara244@gmail.com | H18: \N | I18: Piedecuesta a | J18: \N | K18: 39550 | L18: \N | M18: 2 | N18: 5 | O18: \N | P18: \N | Q18: \N | R18: 7 | S18: Sonia Isabel Bohórquez Vargas | T18: Padre/Madre | U18: 3146061376 | V18: \N | W18: Activo | X18: 45930 | Y18: 0 | AA18: 1
A19: 2261 | B19: 1098625892 | C19: 1 | D19: DANIELA DAYANA | E19: RINCON DIAZ | F19: 3153740663 | G19: cr2386661@gmail.com | H19: \N | I19: \N | J19: \N | K19: 38322 | L19: \N | M19: 2 | N19: 10 | O19: \N | P19: \N | Q19: \N | R19: \N | S19: \N | T19: \N | U19: \N | V19: \N | W19: Pendiente | X19: 45930 | Y19: 0 | Z19: \N | AA19: 18
A20: 2264 | B20: 1090475652 | C20: 1 | D20: David | E20: Escobar | F20: 3022944427 | G20: qqtabox@gmail.com | H20: \N | I20: Ed Alto pamplonita 407 | J20: \N | K20: 34314 | L20: \N | M20: 1 | N20: 6 | O20: \N | P20: \N | Q20: \N | R20: 4 | S20: Myriam | T20: Padre/Madre | U20: 3164538487 | V20: \N | W20: Activo | X20: 45931 | Y20: 0 | AA20: 18
A21: 2275 | B21: 1096700440 | C21: 1 | D21: MAILETH STEFANNY | E21: HURTADO MUÑOZ | F21: 3245568323 | G21: mailethstefanny.h@gmail.com | H21: \N | I21: CRA 15#65-50 | J21: \N | K21: 38234 | L21: \N | M21: 2 | N21: 10 | O21: \N | P21: \N | Q21: \N | R21: 9 | S21: GLORIA ENIT MUÑOZ GOMEZ | T21: Padre/Madre | U21: 3142127071 | V21: \N | W21: Activo | X21: 45931 | Y21: 0 | AA21: 19
A22: 2280 | B22: 1093775147 | C22: 1 | D22: JOICY DAYANNA | E22: SAAVEDRA MEDINA | F22: 3023859906 | G22: saavedrajoicy@gmail.com | H22: \N | I22: Cll 10An # 2A-23 bosque paraiso | J22: \N | K22: 34632 | L22: \N | M22: 2 | N22: 6 | O22: \N | P22: \N | Q22: \N | R22: 5 | S22: Nancy Saavedra | T22: Padre/Madre | U22: 3142944260 | V22: \N | W22: Activo | X22: 45932 | Y22: 0 | AA22: 19
A23: 2284 | B23: 1090535263 | C23: 1 | D23: FREDDY | E23: PARADA ORTEGA | F23: 3135740397 | G23: Freddypara46@gmail.com | H23: \N | I23: \N | J23: \N | K23: 36451 | L23: \N | M23: 1 | N23: 4 | O23: \N | P23: \N | Q23: \N | R23: \N | S23: \N | T23: \N | U23: \N | V23: \N | W23: Pendiente | X23: 45932 | Y23: 0 | Z23: \N | AA23: 1
A24: 2290 | B24: 1097911303 | C24: 1 | D24: LESLY VALENTINA | E24: PINZON PALOMINO | F24: 3001632609 | G24: leslyevalentina4@gmail.com | H24: \N | I24: Calle 7N 7-53 apto 501 edificio Infinity Junín 1 | J24: \N | K24: 38768 | L24: \N | M24: 2 | N24: 5 | O24: \N | P24: \N | Q24: \N | R24: 7 | S24: DIANA CAROLINA PALOMINO | T24: Padre/Madre | U24: 3208307393 | V24: \N | W24: Activo | X24: 45933 | Y24: 0 | AA24: 1
A25: 2294 | B25: 1095934040 | C25: 1 | D25: PAOLA ANDREA | E25: SIERRA LOZANO | F25: 3106732017 | G25: Paosierralozano@gmail.com | H25: \N | I25: Calle 10 22 53 | J25: \N | K25: 34218 | L25: \N | M25: 2 | N25: 8 | O25: \N | P25: \N | Q25: \N | R25: 1 | S25: Gladys Lozano | T25: Padre/Madre | U25: 3102356844 | V25: \N | W25: Activo | X25: 45933 | Y25: 0 | AA25: 1
A26: 2295 | B26: 1005028371 | C26: 1 | D26: MICHELLE DANIELA | E26: BERMON ROMAN | F26: 3114043359 | G26: michellebermon5@gmail.com | H26: \N | I26: Mz D19 lote 13 torcoroma II | J26: \N | K26: 37762 | L26: \N | M26: 2 | N26: 4 | O26: \N | P26: \N | Q26: \N | R26: 4 | S26: Bernarda Roman | T26: Padre/Madre | U26: 3225907946 | V26: \N | W26: Activo | X26: 45933 | Y26: 0 | AA26: 1
A27: 2293 | B27: 1116798906 | C27: 1 | D27: CAMILO ALEJANDRO | E27: SANDOVAL CISNEROS | F27: 3152222034 | G27: alejandro_cisneros94@hotmail.com | H27: \N | I27: \N | J27: \N | K27: 34526 | L27: \N | M27: 1 | N27: 2 | O27: \N | P27: \N | Q27: \N | R27: \N | S27: \N | T27: \N | U27: \N | V27: \N | W27: Pendiente | X27: 45933 | Y27: 0 | Z27: \N | AA27: 1
A28: 2298 | B28: 1093590952 | C28: 1 | D28: Anthony Lizandro | E28: Blanco Villarreal | F28: 3138034366 | G28: anthonygamerz12@gmail.com | H28: \N | I28: Avenida 5B #8-30 Prados del este | J28: \N | K28: 38456 | L28: \N | M28: 1 | N28: 4 | O28: \N | P28: \N | Q28: \N | R28: 4 | S28: Joselin Andrea Villarreal | T28: Padre/Madre | U28: 3102388347 | V28: \N | W28: Activo | X28: 45935 | Y28: 0 | AA28: 19
A29: 2299 | B29: 1090393647 | C29: 1 | D29: JOSELIN ANDREA | E29: VILLARREAL | F29: 3102388347 | G29: jandreavillareal@gmail.com | H29: \N | I29: Av 5B#8-30 Prados del Este | J29: \N | K29: 32275 | L29: \N | M29: 2 | N29: 4 | O29: \N | P29: \N | Q29: \N | R29: 4 | S29: Anthony Blanco | T29: Hijo/a | U29: 3108034366 | V29: \N | W29: Activo | X29: 45935 | Y29: 0 | AA29: 19
A30: 2300 | B30: 1005051293 | C30: 1 | D30: MARIA CAMILA | E30: PARDO REALES | F30: 3133119819 | G30: Mariacamilapardo@outlook.es | H30: \N | I30: Avenida libertadores conjunto residencial prados 1 casa 18 | J30: \N | K30: 36582 | L30: \N | M30: 2 | N30: 4 | O30: \N | P30: \N | Q30: \N | R30: 4 | S30: Nathaly Orozco | T30: Primo/a | U30: +57 316 6866784 | V30: \N | W30: Activo | X30: 45935 | Y30: 0 | AA30: 18
A31: 2176 | B31: 1005372165 | C31: 1 | D31: ANA CAMILA | E31: CAAMAÑO DIAZ | F31: 3124778011 | G31: camilacd0926@gmail.com | H31: \N | I31: Calle 8 # 11-47 | J31: 2 | K31: 37020 | L31: \N | M31: 2 | N31: 3 | O31: \N | P31: \N | Q31: \N | R31: 4 | S31: Samuel Caamaño | T31: Hermano/a | U31: 3172798847 | V31: \N | W31: Activo | X31: 45921 | Y31: 0 | AA31: 1
A32: 2305 | B32: 1005106523 | C32: 1 | D32: LISETTE CARINA | E32: RODRIGUEZ MORENO | F32: 3193334006 | G32: rlisette2002@gmail.com | H32: \N | I32: Cll 64a #17a-77 | J32: \N | K32: 37401 | L32: \N | M32: 2 | N32: 10 | O32: \N | P32: \N | Q32: \N | R32: 7 | S32: Rosa moreno | T32: Padre/Madre | U32: 3153059310 | V32: \N | W32: Activo | X32: 45936 | Y32: 0 | AA32: 19
A33: 2310 | B33: 1098666487 | C33: 1 | D33: MONICA CRISTINA | E33: VELASCO ALARCON | F33: 3224670610 | G33: monicaavelascoo18@gmail.com | H33: \N | I33: CAÑAVERAL | J33: \N | K33: 32358 | L33: \N | M33: 2 | N33: 3 | O33: \N | P33: \N | Q33: \N | R33: 1 | S33: 0 | T33: Padre/Madre | U33: 311123123 | V33: \N | W33: Activo | X33: 45936 | Y33: 0 | AA33: 19
A34: 2311 | B34: 1097109207 | C34: 3 | D34: Daniel Felipe | E34: Hernández Salgado | F34: 3046481368 | G34: dh787797@gmail.com | H34: \N | I34: Villa lina | J34: \N | K34: 40379 | L34: \N | M34: 1 | N34: 5 | O34: \N | P34: \N | Q34: \N | R34: 3 | S34: July Paola | T34: Padre/Madre | U34: 3126180405 | V34: \N | W34: Activo | X34: 45936 | Y34: 0 | AA34: 1
A35: 2312 | B35: 1097912477 | C35: 3 | D35: Angel | E35: Gonzalez | F35: 3012814637 | G35: angeldavid.gonzalez0512@gmail.com | H35: \N | I35: Calle 7N#3A-82 | J35: \N | K35: 39421 | L35: \N | M35: 1 | N35: 5 | O35: \N | P35: \N | Q35: \N | R35: 7 | S35: 312438662 | T35: Padre/Madre | U35: 5700390 | V35: \N | W35: Activo | X35: 45936 | Y35: 0 | AA35: 1
A36: 2315 | B36: 1098817468 | C36: 1 | D36: SHARON DANIELA | E36: ACOSTA VILLARREAL | F36: 3006938763 | G36: SHADAAVI08@GMAIL.COM | H36: \N | I36: \N | J36: \N | K36: 36242 | L36: \N | M36: 2 | N36: 3 | O36: \N | P36: \N | Q36: \N | R36: \N | S36: \N | T36: \N | U36: \N | V36: \N | W36: Pendiente | X36: 45936 | Y36: 0 | Z36: \N | AA36: 19
A37: 2316 | B37: 1010842283 | C37: 3 | D37: Dam Sebastián | E37: Vargas Sarmiento | F37: 3228904885 | G37: damsebastianvargassarmiento@gmail.com | H37: \N | I37: Calle 0 # 5 - 21 | J37: \N | K37: 40368 | L37: \N | M37: 1 | N37: 4 | O37: \N | P37: \N | Q37: \N | R37: 4 | S37: Blanca Sarmiento | T37: Padre/Madre | U37: 3223110942 | V37: \N | W37: Activo | X37: 45936 | Y37: 0 | AA37: 1
A38: 2320 | B38: 1097490380 | C38: 1 | D38: Emmanuel | E38: Gomez | F38: 3174808163 | G38: axnel19@gmail.com | H38: \N | I38: \N | J38: \N | K38: 38367 | L38: \N | M38: 1 | N38: 2 | O38: \N | P38: \N | Q38: \N | R38: \N | S38: \N | T38: \N | U38: \N | V38: \N | W38: Pendiente | X38: 45936 | Y38: 0 | Z38: \N | AA38: 19
A39: 2321 | B39: 1005288015 | C39: 1 | D39: LADY ESTEFANIA | E39: MANTILLA MEJIA | F39: 3173016819 | G39: ladymantillamejia@gmail.com | H39: \N | I39: Carrera 16 no. 3N-09 quinta granada | J39: \N | K39: 37068 | L39: \N | M39: 2 | N39: 5 | O39: \N | P39: \N | Q39: \N | R39: 6 | S39: Sebastián Parra | T39: Esposo/a | U39: 3188942930 | V39: \N | W39: Activo | X39: 45936 | Y39: 0 | Z39: Hipoglicemia | AA39: 19
A40: 2322 | B40: 1005066160 | C40: 1 | D40: RICARDO ALEXIS | E40: PARADA BAUTISTA | F40: 3212512443 | G40: Ricardoalexispb@ufps.edu.co | H40: \N | I40: \N | J40: \N | K40: 36732 | L40: \N | M40: 1 | N40: 6 | O40: \N | P40: \N | Q40: \N | R40: \N | S40: \N | T40: \N | U40: \N | V40: \N | W40: Pendiente | X40: 45936 | Y40: 0 | Z40: \N | AA40: 18
...
